Workbook

Sheet Cover
A1: Bank Reconciliation, Receivables Ageing and MIS Dashboard
A2: Demo Foods Distribution Pvt Ltd: April to September 2026 (sample data)
A3: Cash book to bank statement reconciliation, receivables ageing by customer and region, and a monthly MIS dashboard
A5: Prepared by | B5: Vanshika Jindal
A6: Date | B6: October 2026
A8: Sheet | B8: What it contains
A9: Dashboard | B9: Month selector, sales vs collections, receivables trend, ageing, top customers, regions, and reconciliation status
A10: Setup | B10: As-of date, opening balances, customer master (region and credit days), month list
A11: Sales_Ledger | B11: Invoices with due date, amount received, outstanding, days past due and ageing bucket
A12: Collections | B12: Customer receipts applied to invoices
A13: Cash_Book | B13: The company's bank receipts and payments, each matched to the bank statement by reference
A14: Bank_Statement | B14: Bank entries with running balance, each checked against the cash book
A15: Bank_Recon | B15: Bank reconciliation statement, exception summary with actions, and journals to pass
A16: Receivables | B16: Ageing summary, customer-wise ageing, region summary, days sales outstanding
A17: Controls | B17: 18 checks that compare figures that must agree
A19: How the pieces connect
A20: Invoices go into the sales ledger. Customer receipts are logged in the collections register and reduce what each invoice has outstanding.
A21: Each receipt and payment is entered in the cash book with the bank reference. The bank statement is matched to it on that reference.
A22: Whatever does not match is classed as a timing item, an amount difference, or something only the bank knows about. The reconciliation statement proves the cash book balance to the bank balance.
A24: About the data
A25: Sample data. The business, customers, invoices, receipts and bank entries are illustrative and were created for this exercise; they are not records of a real company. The reconciling items (timing differences, a transposed amount, unrecorded bank charges and interest, an unidentified deposit) are deliberately included to show how each is handled.
A27: Colour code
A28: Blue text | B28: Typed value
A29: Black text | B29: Formula
A30: Green text | B30: Link to another sheet
A31: Yellow fill | B31: Cell you can change (as-of date, opening balances, month selector)

Sheet Dashboard
A1: MIS dashboard: sales, collections and receivables
A2: Pick a month in the yellow cell. Charts and tables read from the ledger, collections and reconciliation sheets.
A4: Select month | B4: Sep-26
A5: Period | B5: =INDEX(Setup!$F$13:$F$18,MATCH($B$4,Setup!$E$13:$E$18,0)) -> 46266 | C5: =EOMONTH(B5,0) -> 46295
A6: Selected month
A7: Sales billed (₹) | B7: =SUMIFS(Sales_Ledger!$E$6:$E$285,Sales_Ledger!$B$6:$B$285,">="&$B$5,Sales_Ledger!$B$6:$B$285,"<="&$C$5) -> 9917973
A8: Invoices raised | B8: =COUNTIFS(Sales_Ledger!$B$6:$B$285,">="&$B$5,Sales_Ledger!$B$6:$B$285,"<="&$C$5) -> 40
A9: Collections received (₹) | B9: =SUMIFS(Collections!$E$6:$E$239,Collections!$B$6:$B$239,">="&$B$5,Collections!$B$6:$B$239,"<="&$C$5) -> 9677675
A10: Collections as % of sales billed | B10: =IF(B7=0,0,B9/B7) -> 0.97577146
A11: Receivables at month-end (₹) | B11: =SUMIFS(Sales_Ledger!$E$6:$E$285,Sales_Ledger!$B$6:$B$285,"<="&$C$5)-SUMIFS(Collections!$E$6:$E$239,Collections!$B$6:$B$239,"<="&$C$5) -> 16749030
A13: Position at as-of date | B13: =Setup!$B$5 -> 46295
A14: Total outstanding (₹) | B14: =Receivables!B10 -> 16749030
A15: Overdue (₹) | B15: =SUMIFS(Sales_Ledger!$I$6:$I$285,Sales_Ledger!$J$6:$J$285,">0") -> 6059096
A16: Overdue as % of outstanding | B16: =IF(B14=0,0,B15/B14) -> 0.36175802
A17: Over 60 days (₹) | B17: =SUMIFS(Sales_Ledger!$I$6:$I$285,Sales_Ledger!$J$6:$J$285,">60") -> 1558760
A18: Days sales outstanding | B18: =Receivables!B14 -> 49.410735
A19: Bank reconciliation: unexplained difference (₹) | B19: =Bank_Recon!B14 -> 0
A20: Bank reconciliation: open items | B20: =Bank_Recon!B24 -> 11
A22: Month by month
A23: Month | B23: Month end | C23: Sales billed (₹) | D23: Collections (₹) | E23: Collections % of sales | F23: Receivables at month-end (₹) | G23: Invoices raised
A24: =Setup!E13 -> Apr-26 | B24: =EOMONTH(Setup!F13,0) -> 46142 | C24: =SUMIFS(Sales_Ledger!$E$6:$E$285,Sales_Ledger!$B$6:$B$285,">="&Setup!F13,Sales_Ledger!$B$6:$B$285,"<="&B24) -> 11630026 | D24: =SUMIFS(Collections!$E$6:$E$239,Collections!$B$6:$B$239,">="&Setup!F13,Collections!$B$6:$B$239,"<="&B24) -> 5879245 | E24: =IF(C24=0,0,D24/C24) -> 0.50552295 | F24: =SUMIFS(Sales_Ledger!$E$6:$E$285,Sales_Ledger!$B$6:$B$285,"<="&B24)-SUMIFS(Collections!$E$6:$E$239,Collections!$B$6:$B$239,"<="&B24) -> 15502262 | G24: =COUNTIFS(Sales_Ledger!$B$6:$B$285,">="&Setup!F13,Sales_Ledger!$B$6:$B$285,"<="&B24) -> 40
A25: =Setup!E14 -> May-26 | B25: =EOMONTH(Setup!F14,0) -> 46173 | C25: =SUMIFS(Sales_Ledger!$E$6:$E$285,Sales_Ledger!$B$6:$B$285,">="&Setup!F14,Sales_Ledger!$B$6:$B$285,"<="&B25) -> 10309503 | D25: =SUMIFS(Collections!$E$6:$E$239,Collections!$B$6:$B$239,">="&Setup!F14,Collections!$B$6:$B$239,"<="&B25) -> 8819741 | E25: =IF(C25=0,0,D25/C25) -> 0.85549623 | F25: =SUMIFS(Sales_Ledger!$E$6:$E$285,Sales_Ledger!$B$6:$B$285,"<="&B25)-SUMIFS(Collections!$E$6:$E$239,Collections!$B$6:$B$239,"<="&B25) -> 16992024 | G25: =COUNTIFS(Sales_Ledger!$B$6:$B$285,">="&Setup!F14,Sales_Ledger!$B$6:$B$285,"<="&B25) -> 40
A26: =Setup!E15 -> Jun-26 | B26: =EOMONTH(Setup!F15,0) -> 46203 | C26: =SUMIFS(Sales_Ledger!$E$6:$E$285,Sales_Ledger!$B$6:$B$285,">="&Setup!F15,Sales_Ledger!$B$6:$B$285,"<="&B26) -> 9534597 | D26: =SUMIFS(Collections!$E$6:$E$239,Collections!$B$6:$B$239,">="&Setup!F15,Collections!$B$6:$B$239,"<="&B26) -> 10615534 | E26: =IF(C26=0,0,D26/C26) -> 1.11337 | F26: =SUMIFS(Sales_Ledger!$E$6:$E$285,Sales_Ledger!$B$6:$B$285,"<="&B26)-SUMIFS(Collections!$E$6:$E$239,Collections!$B$6:$B$239,"<="&B26) -> 15911087 | G26: =COUNTIFS(Sales_Ledger!$B$6:$B$285,">="&Setup!F15,Sales_Ledger!$B$6:$B$285,"<="&B26) -> 40
A27: =Setup!E16 -> Jul-26 | B27: =EOMONTH(Setup!F16,0) -> 46234 | C27: =SUMIFS(Sales_Ledger!$E$6:$E$285,Sales_Ledger!$B$6:$B$285,">="&Setup!F16,Sales_Ledger!$B$6:$B$285,"<="&B27) -> 11749827 | D27: =SUMIFS(Collections!$E$6:$E$239,Collections!$B$6:$B$239,">="&Setup!F16,Collections!$B$6:$B$239,"<="&B27) -> 8811779 | E27: =IF(C27=0,0,D27/C27) -> 0.74994968 | F27: =SUMIFS(Sales_Ledger!$E$6:$E$285,Sales_Ledger!$B$6:$B$285,"<="&B27)-SUMIFS(Collections!$E$6:$E$239,Collections!$B$6:$B$239,"<="&B27) -> 18849135 | G27: =COUNTIFS(Sales_Ledger!$B$6:$B$285,">="&Setup!F16,Sales_Ledger!$B$6:$B$285,"<="&B27) -> 40
A28: =Setup!E17 -> Aug-26 | B28: =EOMONTH(Setup!F17,0) -> 46265 | C28: =SUMIFS(Sales_Ledger!$E$6:$E$285,Sales_Ledger!$B$6:$B$285,">="&Setup!F17,Sales_Ledger!$B$6:$B$285,"<="&B28) -> 8890596 | D28: =SUMIFS(Collections!$E$6:$E$239,Collections!$B$6:$B$239,">="&Setup!F17,Collections!$B$6:$B$239,"<="&B28) -> 11230999 | E28: =IF(C28=0,0,D28/C28) -> 1.2632448 | F28: =SUMIFS(Sales_Ledger!$E$6:$E$285,Sales_Ledger!$B$6:$B$285,"<="&B28)-SUMIFS(Collections!$E$6:$E$239,Collections!$B$6:$B$239,"<="&B28) -> 16508732 | G28: =COUNTIFS(Sales_Ledger!$B$6:$B$285,">="&Setup!F17,Sales_Ledger!$B$6:$B$285,"<="&B28) -> 40
A29: =Setup!E18 -> Sep-26 | B29: =EOMONTH(Setup!F18,0) -> 46295 | C29: =SUMIFS(Sales_Ledger!$E$6:$E$285,Sales_Ledger!$B$6:$B$285,">="&Setup!F18,Sales_Ledger!$B$6:$B$285,"<="&B29) -> 9917973 | D29: =SUMIFS(Collections!$E$6:$E$239,Collections!$B$6:$B$239,">="&Setup!F18,Collections!$B$6:$B$239,"<="&B29) -> 9677675 | E29: =IF(C29=0,0,D29/C29) -> 0.97577146 | F29: =SUMIFS(Sales_Ledger!$E$6:$E$285,Sales_Ledger!$B$6:$B$285,"<="&B29)-SUMIFS(Collections!$E$6:$E$239,Collections!$B$6:$B$239,"<="&B29) -> 16749030 | G29: =COUNTIFS(Sales_Ledger!$B$6:$B$285,">="&Setup!F18,Sales_Ledger!$B$6:$B$285,"<="&B29) -> 40
A30: Period total | C30: =SUM(C24:C29) -> 62032522 | D30: =SUM(D24:D29) -> 55034973 | E30: =IF(C30=0,0,D30/C30) -> 0.88719548 | F30: =F29 -> 16749030 | G30: =SUM(G24:G29) -> 240
A32: Top 5 customers by outstanding | F32: By region
A33: Customer | B33: Outstanding (₹) | C33: Overdue (₹) | D33: % of total | F33: Region | G33: Billed (₹) | H33: Outstanding (₹) | I33: % overdue
A34: =INDEX(Receivables!$A$18:$A$31,MATCH(B34,Receivables!$E$18:$E$31,0)) -> Awadh Agencies, Lucknow | B34: =LARGE(Receivables!$E$18:$E$31,1) -> 3728841 | C34: =B34-INDEX(Receivables!$F$18:$F$31,MATCH(B34,Receivables!$E$18:$E$31,0)) -> 2953190 | D34: =IF($B$14=0,0,B34/$B$14) -> 0.22263027 | F34: =Receivables!A36 -> East | G34: =Receivables!B36 -> 16172440 | H34: =Receivables!D36 -> 2635789 | I34: =Receivables!F36 -> 0.32123095
A35: =INDEX(Receivables!$A$18:$A$31,MATCH(B35,Receivables!$E$18:$E$31,0)) -> Yamuna Traders, Delhi | B35: =LARGE(Receivables!$E$18:$E$31,2) -> 1668228 | C35: =B35-INDEX(Receivables!$F$18:$F$31,MATCH(B35,Receivables!$E$18:$E$31,0)) -> 10631 | D35: =IF($B$14=0,0,B35/$B$14) -> 0.099601469 | F35: =Receivables!A37 -> West | G35: =Receivables!B37 -> 13155611 | H35: =Receivables!D37 -> 2637492 | I35: =Receivables!F37 -> 0.1963623
A36: =INDEX(Receivables!$A$18:$A$31,MATCH(B36,Receivables!$E$18:$E$31,0)) -> Satluj Foods, Ludhiana | B36: =LARGE(Receivables!$E$18:$E$31,3) -> 1572435 | C36: =B36-INDEX(Receivables!$F$18:$F$31,MATCH(B36,Receivables!$E$18:$E$31,0)) -> 218632 | D36: =IF($B$14=0,0,B36/$B$14) -> 0.093882153 | F36: =Receivables!A38 -> North | G36: =Receivables!B38 -> 22656631 | H36: =Receivables!D38 -> 8037098 | I36: =Receivables!F38 -> 0.43000222
A37: =INDEX(Receivables!$A$18:$A$31,MATCH(B37,Receivables!$E$18:$E$31,0)) -> Krishna Distributors, Hyderabad | B37: =LARGE(Receivables!$E$18:$E$31,4) -> 1236810 | C37: =B37-INDEX(Receivables!$F$18:$F$31,MATCH(B37,Receivables!$E$18:$E$31,0)) -> 348546 | D37: =IF($B$14=0,0,B37/$B$14) -> 0.073843679 | F37: =Receivables!A39 -> South | G37: =Receivables!B39 -> 19799321 | H37: =Receivables!D39 -> 3438651 | I37: =Receivables!F39 -> 0.36017758
A38: =INDEX(Receivables!$A$18:$A$31,MATCH(B38,Receivables!$E$18:$E$31,0)) -> Hooghly Foods, Kolkata | B38: =LARGE(Receivables!$E$18:$E$31,5) -> 1233554 | C38: =B38-INDEX(Receivables!$F$18:$F$31,MATCH(B38,Receivables!$E$18:$E$31,0)) -> 406974 | D38: =IF($B$14=0,0,B38/$B$14) -> 0.07364928

Sheet Setup
A1: Setup
A2: Parameters and masters used by every other sheet. Yellow cells can be changed.
A4: Business (sample) | B4: Demo Foods Distribution Pvt Ltd
A5: As-of date | B5: 46295
A6: Period start | B6: 46113
A7: Opening balance per cash book (₹) | B7: 1250000
A8: Opening balance per bank statement (₹) | B8: 1250000 | C8: Opening balances are assumed to be reconciled at the start date.
A9: Match tolerance (₹) | B9: 0.5
A12: Customer | B12: Region | C12: Credit days | E12: Month | F12: Month start | G12: Month no.
A13: Hooghly Foods, Kolkata | B13: East | C13: 30 | E13: Apr-26 | F13: 46113 | G13: =MONTH(F13) -> 4
A14: Brahmaputra Traders, Guwahati | B14: East | C14: 30 | E14: May-26 | F14: 46143 | G14: =MONTH(F14) -> 5
A15: Magadh Agencies, Patna | B15: East | C15: 45 | E15: Jun-26 | F15: 46174 | G15: =MONTH(F15) -> 6
A16: Konkan Distributors, Mumbai | B16: West | C16: 30 | E16: Jul-26 | F16: 46204 | G16: =MONTH(F16) -> 7
A17: Narmada Foods, Surat | B17: West | C17: 30 | E17: Aug-26 | F17: 46235 | G17: =MONTH(F17) -> 8
A18: Marwar Agencies, Jaipur | B18: West | C18: 45 | E18: Sep-26 | F18: 46266 | G18: =MONTH(F18) -> 9
A19: Yamuna Traders, Delhi | B19: North | C19: 30
A20: Satluj Foods, Ludhiana | B20: North | C20: 30
A21: Doon Distributors, Dehradun | B21: North | C21: 30
A22: Awadh Agencies, Lucknow | B22: North | C22: 45
A23: Cauvery Foods, Bengaluru | B23: South | C23: 30
A24: Coromandel Traders, Chennai | B24: South | C24: 30
A25: Krishna Distributors, Hyderabad | B25: South | C25: 30
A26: Periyar Agencies, Kochi | B26: South | C26: 45

Sheet Sales_Ledger
A1: Sales ledger
A2: Invoices raised, with collections, outstanding and ageing worked out by formula. March invoices are the receivables brought forward.
A5: Invoice no. | B5: Date | C5: Customer | D5: Product line | E5: Amount (₹) | F5: Region | G5: Due date | H5: Received (₹) | I5: Outstanding (₹) | J5: Days past due | K5: Ageing bucket
A6: INV/26-27/0001 | B6: 46082 | C6: Hooghly Foods, Kolkata | D6: Cakes | E6: 366402 | F6: =INDEX(Setup!$B$13:$B$26,MATCH(C6,Setup!$A$13:$A$26,0)) -> East | G6: =B6+INDEX(Setup!$C$13:$C$26,MATCH(C6,Setup!$A$13:$A$26,0)) -> 46112 | H6: =SUMIFS(Collections!$E$6:$E$2000,Collections!$C$6:$C$2000,A6) -> 366402 | I6: =E6-H6 -> 0 | J6: =IF(I6>Setup!$B$9,Setup!$B$5-G6,"") | K6: =IF(I6<=Setup!$B$9,"Settled",IF(J6<=0,"Not yet due",IF(J6<=30,"1-30 days",IF(J6<=60,"31-60 days",IF(J6<=90,"61-90 days","Over 90 days"))))) -> Settled
A7: INV/26-27/0002 | B7: 46082 | C7: Magadh Agencies, Patna | D7: Biscuits | E7: 107216 | F7: =INDEX(Setup!$B$13:$B$26,MATCH(C7,Setup!$A$13:$A$26,0)) -> East | G7: =B7+INDEX(Setup!$C$13:$C$26,MATCH(C7,Setup!$A$13:$A$26,0)) -> 46127 | H7: =SUMIFS(Collections!$E$6:$E$2000,Collections!$C$6:$C$2000,A7) -> 107216 | I7: =E7-H7 -> 0 | J7: =IF(I7>Setup!$B$9,Setup!$B$5-G7,"") | K7: =IF(I7<=Setup!$B$9,"Settled",IF(J7<=0,"Not yet due",IF(J7<=30,"1-30 days",IF(J7<=60,"31-60 days",IF(J7<=90,"61-90 days","Over 90 days"))))) -> Settled
A8: INV/26-27/0003 | B8: 46082 | C8: Hooghly Foods, Kolkata | D8: Biscuits | E8: 324643 | F8: =INDEX(Setup!$B$13:$B$26,MATCH(C8,Setup!$A$13:$A$26,0)) -> East | G8: =B8+INDEX(Setup!$C$13:$C$26,MATCH(C8,Setup!$A$13:$A$26,0)) -> 46112 | H8: =SUMIFS(Collections!$E$6:$E$2000,Collections!$C$6:$C$2000,A8) -> 324643 | I8: =E8-H8 -> 0 | J8: =IF(I8>Setup!$B$9,Setup!$B$5-G8,"") | K8: =IF(I8<=Setup!$B$9,"Settled",IF(J8<=0,"Not yet due",IF(J8<=30,"1-30 days",IF(J8<=60,"31-60 days",IF(J8<=90,"61-90 days","Over 90 days"))))) -> Settled
A9: INV/26-27/0004 | B9: 46083 | C9: Hooghly Foods, Kolkata | D9: Biscuits | E9: 401007 | F9: =INDEX(Setup!$B$13:$B$26,MATCH(C9,Setup!$A$13:$A$26,0)) -> East | G9: =B9+INDEX(Setup!$C$13:$C$26,MATCH(C9,Setup!$A$13:$A$26,0)) -> 46113 | H9: =SUMIFS(Collections!$E$6:$E$2000,Collections!$C$6:$C$2000,A9) -> 401007 | I9: =E9-H9 -> 0 | J9: =IF(I9>Setup!$B$9,Setup!$B$5-G9,"") | K9: =IF(I9<=Setup!$B$9,"Settled",IF(J9<=0,"Not yet due",IF(J9<=30,"1-30 days",IF(J9<=60,"31-60 days",IF(J9<=90,"61-90 days","Over 90 days"))))) -> Settled
A10: INV/26-27/0005 | B10: 46084 | C10: Coromandel Traders, Chennai | D10: Biscuits | E10: 214074 | F10: =INDEX(Setup!$B$13:$B$26,MATCH(C10,Setup!$A$13:$A$26,0)) -> South | G10: =B10+INDEX(Setup!$C$13:$C$26,MATCH(C10,Setup!$A$13:$A$26,0)) -> 46114 | H10: =SUMIFS(Collections!$E$6:$E$2000,Collections!$C$6:$C$2000,A10) -> 214074 | I10: =E10-H10 -> 0 | J10: =IF(I10>Setup!$B$9,Setup!$B$5-G10,"") | K10: =IF(I10<=Setup!$B$9,"Settled",IF(J10<=0,"Not yet due",IF(J10<=30,"1-30 days",IF(J10<=60,"31-60 days",IF(J10<=90,"61-90 days","Over 90 days"))))) -> Settled
A11: INV/26-27/0006 | B11: 46084 | C11: Awadh Agencies, Lucknow | D11: Cakes | E11: 226045 | F11: =INDEX(Setup!$B$13:$B$26,MATCH(C11,Setup!$A$13:$A$26,0)) -> North | G11: =B11+INDEX(Setup!$C$13:$C$26,MATCH(C11,Setup!$A$13:$A$26,0)) -> 46129 | H11: =SUMIFS(Collections!$E$6:$E$2000,Collections!$C$6:$C$2000,A11) -> 226045 | I11: =E11-H11 -> 0 | J11: =IF(I11>Setup!$B$9,Setup!$B$5-G11,"") | K11: =IF(I11<=Setup!$B$9,"Settled",IF(J11<=0,"Not yet due",IF(J11<=30,"1-30 days",IF(J11<=60,"31-60 days",IF(J11<=90,"61-90 days","Over 90 days"))))) -> Settled
A12: INV/26-27/0007 | B12: 46084 | C12: Coromandel Traders, Chennai | D12: Rusk | E12: 75545 | F12: =INDEX(Setup!$B$13:$B$26,MATCH(C12,Setup!$A$13:$A$26,0)) -> South | G12: =B12+INDEX(Setup!$C$13:$C$26,MATCH(C12,Setup!$A$13:$A$26,0)) -> 46114 | H12: =SUMIFS(Collections!$E$6:$E$2000,Collections!$C$6:$C$2000,A12) -> 75545 | I12: =E12-H12 -> 0 | J12: =IF(I12>Setup!$B$9,Setup!$B$5-G12,"") | K12: =IF(I12<=Setup!$B$9,"Settled",IF(J12<=0,"Not yet due",IF(J12<=30,"1-30 days",IF(J12<=60,"31-60 days",IF(J12<=90,"61-90 days","Over 90 days"))))) -> Settled
A13: INV/26-27/0008 | B13: 46084 | C13: Hooghly Foods, Kolkata | D13: Biscuits | E13: 273061 | F13: =INDEX(Setup!$B$13:$B$26,MATCH(C13,Setup!$A$13:$A$26,0)) -> East | G13: =B13+INDEX(Setup!$C$13:$C$26,MATCH(C13,Setup!$A$13:$A$26,0)) -> 46114 | H13: =SUMIFS(Collections!$E$6:$E$2000,Collections!$C$6:$C$2000,A13) -> 273061 | I13: =E13-H13 -> 0 | J13: =IF(I13>Setup!$B$9,Setup!$B$5-G13,"") | K13: =IF(I13<=Setup!$B$9,"Settled",IF(J13<=0,"Not yet due",IF(J13<=30,"1-30 days",IF(J13<=60,"31-60 days",IF(J13<=90,"61-90 days","Over 90 days"))))) -> Settled
A14: INV/26-27/0009 | B14: 46085 | C14: Konkan Distributors, Mumbai | D14: Biscuits | E14: 534180 | F14: =INDEX(Setup!$B$13:$B$26,MATCH(C14,Setup!$A$13:$A$26,0)) -> West | G14: =B14+INDEX(Setup!$C$13:$C$26,MATCH(C14,Setup!$A$13:$A$26,0)) -> 46115 | H14: =SUMIFS(Collections!$E$6:$E$2000,Collections!$C$6:$C$2000,A14) -> 534180 | I14: =E14-H14 -> 0 | J14: =IF(I14>Setup!$B$9,Setup!$B$5-G14,"") | K14: =IF(I14<=Setup!$B$9,"Settled",IF(J14<=0,"Not yet due",IF(J14<=30,"1-30 days",IF(J14<=60,"31-60 days",IF(J14<=90,"61-90 days","Over 90 days"))))) -> Settled
A15: INV/26-27/0010 | B15: 46085 | C15: Krishna Distributors, Hyderabad | D15: Biscuits | E15: 457762 | F15: =INDEX(Setup!$B$13:$B$26,MATCH(C15,Setup!$A$13:$A$26,0)) -> South | G15: =B15+INDEX(Setup!$C$13:$C$26,MATCH(C15,Setup!$A$13:$A$26,0)) -> 46115 | H15: =SUMIFS(Collections!$E$6:$E$2000,Collections!$C$6:$C$2000,A15) -> 448606 | I15: =E15-H15 -> 9156 | J15: =IF(I15>Setup!$B$9,Setup!$B$5-G15,"") -> 180 | K15: =IF(I15<=Setup!$B$9,"Settled",IF(J15<=0,"Not yet due",IF(J15<=30,"1-30 days",IF(J15<=60,"31-60 days",IF(J15<=90,"61-90 days","Over 90 days"))))) -> Over 90 days
A16: INV/26-27/0011 | B16: 46086 | C16: Satluj Foods, Ludhiana | D16: Dairy | E16: 204951 | F16: =INDEX(Setup!$B$13:$B$26,MATCH(C16,Setup!$A$13:$A$26,0)) -> North | G16: =B16+INDEX(Setup!$C$13:$C$26,MATCH(C16,Setup!$A$13:$A$26,0)) -> 46116 | H16: =SUMIFS(Collections!$E$6:$E$2000,Collections!$C$6:$C$2000,A16) -> 204951 | I16: =E16-H16 -> 0 | J16: =IF(I16>Setup!$B$9,Setup!$B$5-G16,"") | K16: =IF(I16<=Setup!$B$9,"Settled",IF(J16<=0,"Not yet due",IF(J16<=30,"1-30 days",IF(J16<=60,"31-60 days",IF(J16<=90,"61-90 days","Over 90 days"))))) -> Settled
A17: INV/26-27/0012 | B17: 46086 | C17: Hooghly Foods, Kolkata | D17: Biscuits | E17: 345881 | F17: =INDEX(Setup!$B$13:$B$26,MATCH(C17,Setup!$A$13:$A$26,0)) -> East | G17: =B17+INDEX(Setup!$C$13:$C$26,MATCH(C17,Setup!$A$13:$A$26,0)) -> 46116 | H17: =SUMIFS(Collections!$E$6:$E$2000,Collections!$C$6:$C$2000,A17) -> 345881 | I17: =E17-H17 -> 0 | J17: =IF(I17>Setup!$B$9,Setup!$B$5-G17,"") | K17: =IF(I17<=Setup!$B$9,"Settled",IF(J17<=0,"Not yet due",IF(J17<=30,"1-30 days",IF(J17<=60,"31-60 days",IF(J17<=90,"61-90 days","Over 90 days"))))) -> Settled
... A285: INV/26-27/0280 | B285: 46295 | C285: Krishna Distributors, Hyderabad | D285: Dairy | E285: 405665 | F285: =INDEX(Setup!$B$13:$B$26,MATCH(C285,Setup!$A$13:$A$26,0)) -> South | G285: =B285+INDEX(Setup!$C$13:$C$26,MATCH(C285,Setup!$A$13:$A$26,0)) -> 46325 | H285: =SUMIFS(Collections!$E$6:$E$2000,Collections!$C$6:$C$2000,A285) -> 0 | I285: =E285-H285 -> 405665 | J285: =IF(I285>Setup!$B$9,Setup!$B$5-G285,"") -> -30 | K285: =IF(I285<=Setup!$B$9,"Settled",IF(J285<=0,"Not yet due",IF(J285<=30,"1-30 days",IF(J285<=60,"31-60 days",IF(J285<=90,"61-90 days","Over 90 days"))))) -> Not yet due

Sheet Collections
A1: Collections register
A2: Customer receipts applied to invoices. One invoice can have more than one receipt.
A5: Receipt no. | B5: Date | C5: Invoice no. | D5: Customer | E5: Amount (₹) | F5: Mode | G5: Bank reference | H5: Invoice date
A6: RCP-26-0001 | B6: 46121 | C6: INV/26-27/0010 | D6: =INDEX(Sales_Ledger!$C$6:$C$285,MATCH(C6,Sales_Ledger!$A$6:$A$285,0)) -> Krishna Distributors, Hyderabad | E6: 448606 | F6: NEFT | G6: UTR3584034599 | H6: =INDEX(Sales_Ledger!$B$6:$B$285,MATCH(C6,Sales_Ledger!$A$6:$A$285,0)) -> 46085
A7: RCP-26-0002 | B7: 46122 | C7: INV/26-27/0004 | D7: =INDEX(Sales_Ledger!$C$6:$C$285,MATCH(C7,Sales_Ledger!$A$6:$A$285,0)) -> Hooghly Foods, Kolkata | E7: 210447 | F7: RTGS | G7: UTR3124175006 | H7: =INDEX(Sales_Ledger!$B$6:$B$285,MATCH(C7,Sales_Ledger!$A$6:$A$285,0)) -> 46083
A8: RCP-26-0003 | B8: 46123 | C8: INV/26-27/0008 | D8: =INDEX(Sales_Ledger!$C$6:$C$285,MATCH(C8,Sales_Ledger!$A$6:$A$285,0)) -> Hooghly Foods, Kolkata | E8: 273061 | F8: RTGS | G8: UTR1079250188 | H8: =INDEX(Sales_Ledger!$B$6:$B$285,MATCH(C8,Sales_Ledger!$A$6:$A$285,0)) -> 46084
A9: RCP-26-0004 | B9: 46123 | C9: INV/26-27/0009 | D9: =INDEX(Sales_Ledger!$C$6:$C$285,MATCH(C9,Sales_Ledger!$A$6:$A$285,0)) -> Konkan Distributors, Mumbai | E9: 534180 | F9: Cheque | G9: CHQ640771 | H9: =INDEX(Sales_Ledger!$B$6:$B$285,MATCH(C9,Sales_Ledger!$A$6:$A$285,0)) -> 46085
A10: RCP-26-0005 | B10: 46124 | C10: INV/26-27/0003 | D10: =INDEX(Sales_Ledger!$C$6:$C$285,MATCH(C10,Sales_Ledger!$A$6:$A$285,0)) -> Hooghly Foods, Kolkata | E10: 324643 | F10: RTGS | G10: UTR6847349047 | H10: =INDEX(Sales_Ledger!$B$6:$B$285,MATCH(C10,Sales_Ledger!$A$6:$A$285,0)) -> 46082
A11: RCP-26-0006 | B11: 46124 | C11: INV/26-27/0016 | D11: =INDEX(Sales_Ledger!$C$6:$C$285,MATCH(C11,Sales_Ledger!$A$6:$A$285,0)) -> Brahmaputra Traders, Guwahati | E11: 71313 | F11: NEFT | G11: UTR6345698554 | H11: =INDEX(Sales_Ledger!$B$6:$B$285,MATCH(C11,Sales_Ledger!$A$6:$A$285,0)) -> 46088
A12: RCP-26-0007 | B12: 46125 | C12: INV/26-27/0012 | D12: =INDEX(Sales_Ledger!$C$6:$C$285,MATCH(C12,Sales_Ledger!$A$6:$A$285,0)) -> Hooghly Foods, Kolkata | E12: 345881 | F12: RTGS | G12: UTR1015548088 | H12: =INDEX(Sales_Ledger!$B$6:$B$285,MATCH(C12,Sales_Ledger!$A$6:$A$285,0)) -> 46086
A13: RCP-26-0008 | B13: 46126 | C13: INV/26-27/0013 | D13: =INDEX(Sales_Ledger!$C$6:$C$285,MATCH(C13,Sales_Ledger!$A$6:$A$285,0)) -> Brahmaputra Traders, Guwahati | E13: 302522 | F13: RTGS | G13: UTR2997834210 | H13: =INDEX(Sales_Ledger!$B$6:$B$285,MATCH(C13,Sales_Ledger!$A$6:$A$285,0)) -> 46086
A14: RCP-26-0009 | B14: 46128 | C14: INV/26-27/0017 | D14: =INDEX(Sales_Ledger!$C$6:$C$285,MATCH(C14,Sales_Ledger!$A$6:$A$285,0)) -> Doon Distributors, Dehradun | E14: 160355 | F14: NEFT | G14: UTR2899276652 | H14: =INDEX(Sales_Ledger!$B$6:$B$285,MATCH(C14,Sales_Ledger!$A$6:$A$285,0)) -> 46089
A15: RCP-26-0010 | B15: 46130 | C15: INV/26-27/0001 | D15: =INDEX(Sales_Ledger!$C$6:$C$285,MATCH(C15,Sales_Ledger!$A$6:$A$285,0)) -> Hooghly Foods, Kolkata | E15: 366402 | F15: NEFT | G15: UTR1717359616 | H15: =INDEX(Sales_Ledger!$B$6:$B$285,MATCH(C15,Sales_Ledger!$A$6:$A$285,0)) -> 46082
A16: RCP-26-0011 | B16: 46130 | C16: INV/26-27/0014 | D16: =INDEX(Sales_Ledger!$C$6:$C$285,MATCH(C16,Sales_Ledger!$A$6:$A$285,0)) -> Krishna Distributors, Hyderabad | E16: 166080 | F16: Cheque | G16: CHQ520239 | H16: =INDEX(Sales_Ledger!$B$6:$B$285,MATCH(C16,Sales_Ledger!$A$6:$A$285,0)) -> 46088
A17: RCP-26-0012 | B17: 46131 | C17: INV/26-27/0007 | D17: =INDEX(Sales_Ledger!$C$6:$C$285,MATCH(C17,Sales_Ledger!$A$6:$A$285,0)) -> Coromandel Traders, Chennai | E17: 51198 | F17: Cheque | G17: CHQ439636 | H17: =INDEX(Sales_Ledger!$B$6:$B$285,MATCH(C17,Sales_Ledger!$A$6:$A$285,0)) -> 46084
... A239: RCP-26-0234 | B239: 46295 | C239: INV/26-27/0224 | D239: =INDEX(Sales_Ledger!$C$6:$C$285,MATCH(C239,Sales_Ledger!$A$6:$A$285,0)) -> Doon Distributors, Dehradun | E239: 272065 | F239: Cheque | G239: CHQ726286 | H239: =INDEX(Sales_Ledger!$B$6:$B$285,MATCH(C239,Sales_Ledger!$A$6:$A$285,0)) -> 46250

Sheet Cash_Book
A1: Cash book (bank account)
A2: The company's own record of bank receipts and payments. Each entry is matched to the bank statement on its reference.
A5: Date | B5: Voucher no. | C5: Particulars | D5: Type | E5: Amount (₹) | F5: Net (₹) | G5: Reference | H5: Per bank (₹) | I5: Bank less books (₹) | J5: Status
A6: 46113 | B6: PV-26-0001 | C6: Salary and wages - Mar | D6: Payment | E6: 370000 | F6: =IF(D6="Receipt",E6,-E6) -> -370000 | G6: UTR4286505316 | H6: =IFERROR(INDEX(Bank_Statement!$F$6:$F$303,MATCH(G6,Bank_Statement!$C$6:$C$303,0)),"Not in bank") -> -370000 | I6: =IF(ISNUMBER(H6),H6-F6,"") -> 0 | J6: =IF(NOT(ISNUMBER(H6)),"Not in bank",IF(ABS(I6)<=Setup!$B$9,"Matched","Amount difference")) -> Matched
A7: 46114 | B7: PV-26-0002 | C7: Payment to Flexi Packaging | D7: Payment | E7: 23332 | F7: =IF(D7="Receipt",E7,-E7) -> -23332 | G7: UTR4620991833 | H7: =IFERROR(INDEX(Bank_Statement!$F$6:$F$303,MATCH(G7,Bank_Statement!$C$6:$C$303,0)),"Not in bank") -> -23332 | I7: =IF(ISNUMBER(H7),H7-F7,"") -> 0 | J7: =IF(NOT(ISNUMBER(H7)),"Not in bank",IF(ABS(I7)<=Setup!$B$9,"Matched","Amount difference")) -> Matched
A8: 46117 | B8: PV-26-0003 | C8: Office and godown rent | D8: Payment | E8: 95000 | F8: =IF(D8="Receipt",E8,-E8) -> -95000 | G8: UTR4014921623 | H8: =IFERROR(INDEX(Bank_Statement!$F$6:$F$303,MATCH(G8,Bank_Statement!$C$6:$C$303,0)),"Not in bank") -> -95000 | I8: =IF(ISNUMBER(H8),H8-F8,"") -> 0 | J8: =IF(NOT(ISNUMBER(H8)),"Not in bank",IF(ABS(I8)<=Setup!$B$9,"Matched","Amount difference")) -> Matched
A9: 46121 | B9: RCP-26-0001 | C9: Receipt from Krishna Distributors, Hyderabad against INV/26-27/0010 | D9: Receipt | E9: 448606 | F9: =IF(D9="Receipt",E9,-E9) -> 448606 | G9: UTR3584034599 | H9: =IFERROR(INDEX(Bank_Statement!$F$6:$F$303,MATCH(G9,Bank_Statement!$C$6:$C$303,0)),"Not in bank") -> 448606 | I9: =IF(ISNUMBER(H9),H9-F9,"") -> 0 | J9: =IF(NOT(ISNUMBER(H9)),"Not in bank",IF(ABS(I9)<=Setup!$B$9,"Matched","Amount difference")) -> Matched
A10: 46122 | B10: RCP-26-0002 | C10: Receipt from Hooghly Foods, Kolkata against INV/26-27/0004 | D10: Receipt | E10: 210447 | F10: =IF(D10="Receipt",E10,-E10) -> 210447 | G10: UTR3124175006 | H10: =IFERROR(INDEX(Bank_Statement!$F$6:$F$303,MATCH(G10,Bank_Statement!$C$6:$C$303,0)),"Not in bank") -> 210447 | I10: =IF(ISNUMBER(H10),H10-F10,"") -> 0 | J10: =IF(NOT(ISNUMBER(H10)),"Not in bank",IF(ABS(I10)<=Setup!$B$9,"Matched","Amount difference")) -> Matched
A11: 46122 | B11: PV-26-0004 | C11: Payment to Rapid Roadways | D11: Payment | E11: 24592 | F11: =IF(D11="Receipt",E11,-E11) -> -24592 | G11: CHQ826512 | H11: =IFERROR(INDEX(Bank_Statement!$F$6:$F$303,MATCH(G11,Bank_Statement!$C$6:$C$303,0)),"Not in bank") -> -24592 | I11: =IF(ISNUMBER(H11),H11-F11,"") -> 0 | J11: =IF(NOT(ISNUMBER(H11)),"Not in bank",IF(ABS(I11)<=Setup!$B$9,"Matched","Amount difference")) -> Matched
A12: 46122 | B12: PV-26-0005 | C12: Payment to principal - stock purchase | D12: Payment | E12: 567000 | F12: =IF(D12="Receipt",E12,-E12) -> -567000 | G12: UTR5815071420 | H12: =IFERROR(INDEX(Bank_Statement!$F$6:$F$303,MATCH(G12,Bank_Statement!$C$6:$C$303,0)),"Not in bank") -> -567000 | I12: =IF(ISNUMBER(H12),H12-F12,"") -> 0 | J12: =IF(NOT(ISNUMBER(H12)),"Not in bank",IF(ABS(I12)<=Setup!$B$9,"Matched","Amount difference")) -> Matched
A13: 46123 | B13: RCP-26-0003 | C13: Receipt from Hooghly Foods, Kolkata against INV/26-27/0008 | D13: Receipt | E13: 273061 | F13: =IF(D13="Receipt",E13,-E13) -> 273061 | G13: UTR1079250188 | H13: =IFERROR(INDEX(Bank_Statement!$F$6:$F$303,MATCH(G13,Bank_Statement!$C$6:$C$303,0)),"Not in bank") -> 273061 | I13: =IF(ISNUMBER(H13),H13-F13,"") -> 0 | J13: =IF(NOT(ISNUMBER(H13)),"Not in bank",IF(ABS(I13)<=Setup!$B$9,"Matched","Amount difference")) -> Matched
A14: 46123 | B14: RCP-26-0004 | C14: Receipt from Konkan Distributors, Mumbai against INV/26-27/0009 | D14: Receipt | E14: 534180 | F14: =IF(D14="Receipt",E14,-E14) -> 534180 | G14: CHQ640771 | H14: =IFERROR(INDEX(Bank_Statement!$F$6:$F$303,MATCH(G14,Bank_Statement!$C$6:$C$303,0)),"Not in bank") -> 534180 | I14: =IF(ISNUMBER(H14),H14-F14,"") -> 0 | J14: =IF(NOT(ISNUMBER(H14)),"Not in bank",IF(ABS(I14)<=Setup!$B$9,"Matched","Amount difference")) -> Matched
A15: 46124 | B15: RCP-26-0005 | C15: Receipt from Hooghly Foods, Kolkata against INV/26-27/0003 | D15: Receipt | E15: 324643 | F15: =IF(D15="Receipt",E15,-E15) -> 324643 | G15: UTR6847349047 | H15: =IFERROR(INDEX(Bank_Statement!$F$6:$F$303,MATCH(G15,Bank_Statement!$C$6:$C$303,0)),"Not in bank") -> 324643 | I15: =IF(ISNUMBER(H15),H15-F15,"") -> 0 | J15: =IF(NOT(ISNUMBER(H15)),"Not in bank",IF(ABS(I15)<=Setup!$B$9,"Matched","Amount difference")) -> Matched
A16: 46124 | B16: RCP-26-0006 | C16: Receipt from Brahmaputra Traders, Guwahati against INV/26-27/0016 | D16: Receipt | E16: 71313 | F16: =IF(D16="Receipt",E16,-E16) -> 71313 | G16: UTR6345698554 | H16: =IFERROR(INDEX(Bank_Statement!$F$6:$F$303,MATCH(G16,Bank_Statement!$C$6:$C$303,0)),"Not in bank") -> 71313 | I16: =IF(ISNUMBER(H16),H16-F16,"") -> 0 | J16: =IF(NOT(ISNUMBER(H16)),"Not in bank",IF(ABS(I16)<=Setup!$B$9,"Matched","Amount difference")) -> Matched
A17: 46125 | B17: RCP-26-0007 | C17: Receipt from Hooghly Foods, Kolkata against INV/26-27/0012 | D17: Receipt | E17: 345881 | F17: =IF(D17="Receipt",E17,-E17) -> 345881 | G17: UTR1015548088 | H17: =IFERROR(INDEX(Bank_Statement!$F$6:$F$303,MATCH(G17,Bank_Statement!$C$6:$C$303,0)),"Not in bank") -> 345881 | I17: =IF(ISNUMBER(H17),H17-F17,"") -> 0 | J17: =IF(NOT(ISNUMBER(H17)),"Not in bank",IF(ABS(I17)<=Setup!$B$9,"Matched","Amount difference")) -> Matched
... A304: 46295 | B304: RCP-26-0234 | C304: Receipt from Doon Distributors, Dehradun against INV/26-27/0224 | D304: Receipt | E304: 272065 | F304: =IF(D304="Receipt",E304,-E304) -> 272065 | G304: CHQ726286 | H304: =IFERROR(INDEX(Bank_Statement!$F$6:$F$303,MATCH(G304,Bank_Statement!$C$6:$C$303,0)),"Not in bank") -> Not in bank | I304: =IF(ISNUMBER(H304),H304-F304,"") | J304: =IF(NOT(ISNUMBER(H304)),"Not in bank",IF(ABS(I304)<=Setup!$B$9,"Matched","Amount difference")) -> Not in bank

Sheet Bank_Statement
A1: Bank statement
A2: As received from the bank for the period. Status shows whether the entry has been found in the cash book.
A5: Date | B5: Narration | C5: Reference | D5: Debit (₹) | E5: Credit (₹) | F5: Net (₹) | G5: Running balance (₹) | H5: Category | I5: In cash book?
A6: 46114 | B6: NEFT DR-UTR4286505316-SALARY AND WAGES - MAR | C6: UTR4286505316 | D6: 370000 | F6: =N(E6)-N(D6) -> -370000 | G6: =Setup!$B$8+SUM($F$6:F6) -> 880000 | H6: Salary | I6: =IF(COUNTIF(Cash_Book!$G$6:$G$304,C6)=0,"Not in books","In books") -> In books
A7: 46115 | B7: NEFT DR-UTR4620991833-FLEXI PACKAGING | C7: UTR4620991833 | D7: 23332 | F7: =N(E7)-N(D7) -> -23332 | G7: =Setup!$B$8+SUM($F$6:F7) -> 856668 | H7: Supplier | I7: =IF(COUNTIF(Cash_Book!$G$6:$G$304,C7)=0,"Not in books","In books") -> In books
A8: 46118 | B8: NEFT DR-UTR4014921623-OFFICE AND GODOWN RENT | C8: UTR4014921623 | D8: 95000 | F8: =N(E8)-N(D8) -> -95000 | G8: =Setup!$B$8+SUM($F$6:F8) -> 761668 | H8: Rent | I8: =IF(COUNTIF(Cash_Book!$G$6:$G$304,C8)=0,"Not in books","In books") -> In books
A9: 46121 | B9: NEFT CR-UTR3584034599-KRISHNA DISTRIBUTORS | C9: UTR3584034599 | E9: 448606 | F9: =N(E9)-N(D9) -> 448606 | G9: =Setup!$B$8+SUM($F$6:F9) -> 1210274 | H9: Customer receipt | I9: =IF(COUNTIF(Cash_Book!$G$6:$G$304,C9)=0,"Not in books","In books") -> In books
A10: 46122 | B10: RTGS DR-UTR5815071420-PRINCIPAL - STOCK PURCHASE | C10: UTR5815071420 | D10: 567000 | F10: =N(E10)-N(D10) -> -567000 | G10: =Setup!$B$8+SUM($F$6:F10) -> 643274 | H10: Stock purchase | I10: =IF(COUNTIF(Cash_Book!$G$6:$G$304,C10)=0,"Not in books","In books") -> In books
A11: 46123 | B11: RTGS CR-UTR3124175006-HOOGHLY FOODS | C11: UTR3124175006 | E11: 210447 | F11: =N(E11)-N(D11) -> 210447 | G11: =Setup!$B$8+SUM($F$6:F11) -> 853721 | H11: Customer receipt | I11: =IF(COUNTIF(Cash_Book!$G$6:$G$304,C11)=0,"Not in books","In books") -> In books
A12: 46123 | B12: RTGS CR-UTR1079250188-HOOGHLY FOODS | C12: UTR1079250188 | E12: 273061 | F12: =N(E12)-N(D12) -> 273061 | G12: =Setup!$B$8+SUM($F$6:F12) -> 1126782 | H12: Customer receipt | I12: =IF(COUNTIF(Cash_Book!$G$6:$G$304,C12)=0,"Not in books","In books") -> In books
A13: 46124 | B13: NEFT CR-UTR6345698554-BRAHMAPUTRA TRADERS | C13: UTR6345698554 | E13: 71313 | F13: =N(E13)-N(D13) -> 71313 | G13: =Setup!$B$8+SUM($F$6:F13) -> 1198095 | H13: Customer receipt | I13: =IF(COUNTIF(Cash_Book!$G$6:$G$304,C13)=0,"Not in books","In books") -> In books
A14: 46125 | B14: RTGS CR-UTR6847349047-HOOGHLY FOODS | C14: UTR6847349047 | E14: 324643 | F14: =N(E14)-N(D14) -> 324643 | G14: =Setup!$B$8+SUM($F$6:F14) -> 1522738 | H14: Customer receipt | I14: =IF(COUNTIF(Cash_Book!$G$6:$G$304,C14)=0,"Not in books","In books") -> In books
A15: 46125 | B15: RTGS CR-UTR1015548088-HOOGHLY FOODS | C15: UTR1015548088 | E15: 345881 | F15: =N(E15)-N(D15) -> 345881 | G15: =Setup!$B$8+SUM($F$6:F15) -> 1868619 | H15: Customer receipt | I15: =IF(COUNTIF(Cash_Book!$G$6:$G$304,C15)=0,"Not in books","In books") -> In books
A16: 46126 | B16: Cheque CR-CHQ640771-KONKAN DISTRIBUTORS | C16: CHQ640771 | E16: 534180 | F16: =N(E16)-N(D16) -> 534180 | G16: =Setup!$B$8+SUM($F$6:F16) -> 2402799 | H16: Customer receipt | I16: =IF(COUNTIF(Cash_Book!$G$6:$G$304,C16)=0,"Not in books","In books") -> In books
A17: 46127 | B17: RTGS CR-UTR2997834210-BRAHMAPUTRA TRADERS | C17: UTR2997834210 | E17: 302522 | F17: =N(E17)-N(D17) -> 302522 | G17: =Setup!$B$8+SUM($F$6:F17) -> 2705321 | H17: Customer receipt | I17: =IF(COUNTIF(Cash_Book!$G$6:$G$304,C17)=0,"Not in books","In books") -> In books
A18: 46128 | B18: CHQ PAID CHQ826512-RAPID ROADWAYS | C18: CHQ826512 | D18: 24592 | F18: =N(E18)-N(D18) -> -24592 | G18: =Setup!$B$8+SUM($F$6:F18) -> 2680729 | H18: Supplier | I18: =IF(COUNTIF(Cash_Book!$G$6:$G$304,C18)=0,"Not in books","In books") -> In books
A19: 46129 | B19: NEFT CR-UTR2899276652-DOON DISTRIBUTORS | C19: UTR2899276652 | E19: 160355 | F19: =N(E19)-N(D19) -> 160355 | G19: =Setup!$B$8+SUM($F$6:F19) -> 2841084 | H19: Customer receipt | I19: =IF(COUNTIF(Cash_Book!$G$6:$G$304,C19)=0,"Not in books","In books") -> In books
A20: 46130 | B20: NEFT CR-UTR1717359616-HOOGHLY FOODS | C20: UTR1717359616 | E20: 366402 | F20: =N(E20)-N(D20) -> 366402 | G20: =Setup!$B$8+SUM($F$6:F20) -> 3207486 | H20: Customer receipt | I20: =IF(COUNTIF(Cash_Book!$G$6:$G$304,C20)=0,"Not in books","In books") -> In books
A21: 46132 | B21: NEFT DR-UTR0996350507-GST PAYMENT | C21: UTR0996350507 | D21: 260000 | F21: =N(E21)-N(D21) -> -260000 | G21: =Setup!$B$8+SUM($F$6:F21) -> 2947486 | H21: Tax | I21: =IF(COUNTIF(Cash_Book!$G$6:$G$304,C21)=0,"Not in books","In books") -> In books
A22: 46133 | B22: Cheque CR-CHQ520239-KRISHNA DISTRIBUTORS | C22: CHQ520239 | E22: 166080 | F22: =N(E22)-N(D22) -> 166080 | G22: =Setup!$B$8+SUM($F$6:F22) -> 3113566 | H22: Customer receipt | I22: =IF(COUNTIF(Cash_Book!$G$6:$G$304,C22)=0,"Not in books","In books") -> In books
A23: 46133 | B23: NEFT CR-UTR6626445643-SATLUJ FOODS | C23: UTR6626445643 | E23: 116836 | F23: =N(E23)-N(D23) -> 116836 | G23: =Setup!$B$8+SUM($F$6:F23) -> 3230402 | H23: Customer receipt | I23: =IF(COUNTIF(Cash_Book!$G$6:$G$304,C23)=0,"Not in books","In books") -> In books
A24: 46134 | B24: CHQ PAID CHQ686838-CITY COURIERS | C24: CHQ686838 | D24: 83475 | F24: =N(E24)-N(D24) -> -83475 | G24: =Setup!$B$8+SUM($F$6:F24) -> 3146927 | H24: Supplier | I24: =IF(COUNTIF(Cash_Book!$G$6:$G$304,C24)=0,"Not in books","In books") -> In books
A25: 46134 | B25: Cheque CR-CHQ439636-COROMANDEL TRADERS | C25: CHQ439636 | E25: 51198 | F25: =N(E25)-N(D25) -> 51198 | G25: =Setup!$B$8+SUM($F$6:F25) -> 3198125 | H25: Customer receipt | I25: =IF(COUNTIF(Cash_Book!$G$6:$G$304,C25)=0,"Not in books","In books") -> In books
A26: 46134 | B26: NEFT CR-UTR0761784439-HOOGHLY FOODS | C26: UTR0761784439 | E26: 190560 | F26: =N(E26)-N(D26) -> 190560 | G26: =Setup!$B$8+SUM($F$6:F26) -> 3388685 | H26: Customer receipt | I26: =IF(COUNTIF(Cash_Book!$G$6:$G$304,C26)=0,"Not in books","In books") -> In books
A27: 46135 | B27: NEFT DR-UTR3492945911-BRANDWAVE MEDIA | C27: UTR3492945911 | D27: 71146 | F27: =N(E27)-N(D27) -> -71146 | G27: =Setup!$B$8+SUM($F$6:F27) -> 3317539 | H27: Supplier | I27: =IF(COUNTIF(Cash_Book!$G$6:$G$304,C27)=0,"Not in books","In books") -> In books
A28: 46135 | B28: RTGS CR-UTR4179258705-SATLUJ FOODS | C28: UTR4179258705 | E28: 274315 | F28: =N(E28)-N(D28) -> 274315 | G28: =Setup!$B$8+SUM($F$6:F28) -> 3591854 | H28: Customer receipt | I28: =IF(COUNTIF(Cash_Book!$G$6:$G$304,C28)=0,"Not in books","In books") -> In books
A29: 46136 | B29: Cheque CR-CHQ779202-COROMANDEL TRADERS | C29: CHQ779202 | E29: 214074 | F29: =N(E29)-N(D29) -> 214074 | G29: =Setup!$B$8+SUM($F$6:F29) -> 3805928 | H29: Customer receipt | I29: =IF(COUNTIF(Cash_Book!$G$6:$G$304,C29)=0,"Not in books","In books") -> In books
A30: 46137 | B30: NEFT CR-UTR2517826915-SATLUJ FOODS | C30: UTR2517826915 | E30: 100844 | F30: =N(E30)-N(D30) -> 100844 | G30: =Setup!$B$8+SUM($F$6:F30) -> 3906772 | H30: Customer receipt | I30: =IF(COUNTIF(Cash_Book!$G$6:$G$304,C30)=0,"Not in books","In books") -> In books
A31: 46137 | B31: RTGS DR-UTR9422303073-PRINCIPAL - STOCK PURCHASE | C31: UTR9422303073 | D31: 3003000 | F31: =N(E31)-N(D31) -> -3003000 | G31: =Setup!$B$8+SUM($F$6:F31) -> 903772 | H31: Stock purchase | I31: =IF(COUNTIF(Cash_Book!$G$6:$G$304,C31)=0,"Not in books","In books") -> In books
A32: 46139 | B32: CHQ PAID CHQ220115-PACK-RITE INDUSTRIES | C32: CHQ220115 | D32: 119694 | F32: =N(E32)-N(D32) -> -119694 | G32: =Setup!$B$8+SUM($F$6:F32) -> 784078 | H32: Supplier | I32: =IF(COUNTIF(Cash_Book!$G$6:$G$304,C32)=0,"Not in books","In books") -> In books
A33: 46139 | B33: NEFT CR-UTR7636944783-SATLUJ FOODS | C33: UTR7636944783 | E33: 283842 | F33: =N(E33)-N(D33) -> 283842 | G33: =Setup!$B$8+SUM($F$6:F33) -> 1067920 | H33: Customer receipt | I33: =IF(COUNTIF(Cash_Book!$G$6:$G$304,C33)=0,"Not in books","In books") -> In books
A34: 46139 | B34: NEFT DR-UTR9739760947-PACK-RITE INDUSTRIES | C34: UTR9739760947 | D34: 170607 | F34: =N(E34)-N(D34) -> -170607 | G34: =Setup!$B$8+SUM($F$6:F34) -> 897313 | H34: Supplier | I34: =IF(COUNTIF(Cash_Book!$G$6:$G$304,C34)=0,"Not in books","In books") -> In books
A35: 46139 | B35: RTGS CR-UTR4522683864-SATLUJ FOODS | C35: UTR4522683864 | E35: 242300 | F35: =N(E35)-N(D35) -> 242300 | G35: =Setup!$B$8+SUM($F$6:F35) -> 1139613 | H35: Customer receipt | I35: =IF(COUNTIF(Cash_Book!$G$6:$G$304,C35)=0,"Not in books","In books") -> In books
A36: 46140 | B36: RTGS CR-UTR4667306640-SATLUJ FOODS | C36: UTR4667306640 | E36: 403095 | F36: =N(E36)-N(D36) -> 403095 | G36: =Setup!$B$8+SUM($F$6:F36) -> 1542708 | H36: Customer receipt | I36: =IF(COUNTIF(Cash_Book!$G$6:$G$304,C36)=0,"Not in books","In books") -> In books
A37: 46140 | B37: NEFT DR-UTR3263649654-SHREE WAREHOUSING | C37: UTR3263649654 | D37: 123083 | F37: =N(E37)-N(D37) -> -123083 | G37: =Setup!$B$8+SUM($F$6:F37) -> 1419625 | H37: Supplier | I37: =IF(COUNTIF(Cash_Book!$G$6:$G$304,C37)=0,"Not in books","In books") -> In books
A38: 46141 | B38: Cheque CR-CHQ128261-BRAHMAPUTRA TRADERS | C38: CHQ128261 | E38: 126314 | F38: =N(E38)-N(D38) -> 126314 | G38: =Setup!$B$8+SUM($F$6:F38) -> 1545939 | H38: Customer receipt | I38: =IF(COUNTIF(Cash_Book!$G$6:$G$304,C38)=0,"Not in books","In books") -> In books
A39: 46141 | B39: NEFT CR-UTR2360160594-BRAHMAPUTRA TRADERS | C39: UTR2360160594 | E39: 90454 | F39: =N(E39)-N(D39) -> 90454 | G39: =Setup!$B$8+SUM($F$6:F39) -> 1636393 | H39: Customer receipt | I39: =IF(COUNTIF(Cash_Book!$G$6:$G$304,C39)=0,"Not in books","In books") -> In books
A40: 46141 | B40: NEFT CR-UTR1348128021-SATLUJ FOODS | C40: UTR1348128021 | E40: 287689 | F40: =N(E40)-N(D40) -> 287689 | G40: =Setup!$B$8+SUM($F$6:F40) -> 1924082 | H40: Customer receipt | I40: =IF(COUNTIF(Cash_Book!$G$6:$G$304,C40)=0,"Not in books","In books") -> In books
A41: 46142 | B41: BANK CHARGES - APR | C41: BNKCHG2604 | D41: 590 | F41: =N(E41)-N(D41) -> -590 | G41: =Setup!$B$8+SUM($F$6:F41) -> 1923492 | H41: Bank charges | I41: =IF(COUNTIF(Cash_Book!$G$6:$G$304,C41)=0,"Not in books","In books") -> In books
A42: 46143 | B42: NEFT CR-UTR9907232492-HOOGHLY FOODS | C42: UTR9907232492 | E42: 294234 | F42: =N(E42)-N(D42) -> 294234 | G42: =Setup!$B$8+SUM($F$6:F42) -> 2217726 | H42: Customer receipt | I42: =IF(COUNTIF(Cash_Book!$G$6:$G$304,C42)=0,"Not in books","In books") -> In books
...

Sheet Bank_Recon
A1: Bank reconciliation statement
A2: Cash book to bank statement, as of the as-of date on Setup. Every line is a formula on Cash_Book and Bank_Statement.
A3: As of | B3: =Setup!$B$5 -> 46295
B5: ₹ | C5: What it is
A6: Balance as per cash book | B6: =Setup!$B$7+SUM(Cash_Book!$F$6:$F$304) -> 3093167 | C6: Opening balance plus all cash book entries
A7: Less: receipts in books, not yet credited by bank | B7: =-SUMIFS(Cash_Book!$F$6:$F$304,Cash_Book!$J$6:$J$304,"Not in bank",Cash_Book!$F$6:$F$304,">0") -> -426321 | C7: Deposits in transit
A8: Add: payments in books, not yet debited by bank | B8: =-SUMIFS(Cash_Book!$F$6:$F$304,Cash_Book!$J$6:$J$304,"Not in bank",Cash_Book!$F$6:$F$304,"<0") -> 193700 | C8: Cheques issued but not yet presented
A9: Add / (less): amount differences on matched items | B9: =SUMIFS(Cash_Book!$I$6:$I$304,Cash_Book!$J$6:$J$304,"Amount difference") -> 782 | C9: Bank amount less books amount; needs correction or follow-up
A10: Add: bank credits not yet in books | B10: =SUMIFS(Bank_Statement!$F$6:$F$303,Bank_Statement!$I$6:$I$303,"Not in books",Bank_Statement!$F$6:$F$303,">0") -> 188865 | C10: Interest and unidentified deposits
A11: Less: bank debits not yet in books | B11: =SUMIFS(Bank_Statement!$F$6:$F$303,Bank_Statement!$I$6:$I$303,"Not in books",Bank_Statement!$F$6:$F$303,"<0") -> -1002 | C11: Bank and cheque return charges
A12: Balance as per bank statement (worked out) | B12: =SUM(B6:B11) -> 3049191
A13: Balance as per bank statement (closing balance shown) | B13: =Bank_Statement!G303 -> 3049191 | C13: Last running balance on the statement
A14: Unexplained difference (should be 0) | B14: =ROUND(B12-B13,2) -> 0
A16: Exceptions and what to do about them
A17: Type | B17: Count | C17: Net amount (₹) | D17: Action
A18: Matched entries | B18: =COUNTIF(Cash_Book!$J$6:$J$304,"Matched") -> 292 | C18: =SUMIFS(Cash_Book!$F$6:$F$304,Cash_Book!$J$6:$J$304,"Matched") -> 1440808 | D18: None
A19: Amount differences | B19: =COUNTIF(Cash_Book!$J$6:$J$304,"Amount difference") -> 2 | C19: =SUMIFS(Cash_Book!$I$6:$I$304,Cash_Book!$J$6:$J$304,"Amount difference") -> 782 | D19: Check the receipt against the bank advice, correct the cash book or raise it with the customer
A20: In books, not in bank: receipts | B20: =COUNTIFS(Cash_Book!$J$6:$J$304,"Not in bank",Cash_Book!$F$6:$F$304,">0") -> 2 | C20: =SUMIFS(Cash_Book!$F$6:$F$304,Cash_Book!$J$6:$J$304,"Not in bank",Cash_Book!$F$6:$F$304,">0") -> 426321 | D20: Timing. Confirm they clear in the next statement
A21: In books, not in bank: payments | B21: =COUNTIFS(Cash_Book!$J$6:$J$304,"Not in bank",Cash_Book!$F$6:$F$304,"<0") -> 3 | C21: =SUMIFS(Cash_Book!$F$6:$F$304,Cash_Book!$J$6:$J$304,"Not in bank",Cash_Book!$F$6:$F$304,"<0") -> -193700 | D21: Timing. Follow up cheques not presented after 3 months
A22: In bank, not in books: credits | B22: =COUNTIFS(Bank_Statement!$I$6:$I$303,"Not in books",Bank_Statement!$F$6:$F$303,">0") -> 2 | C22: =SUMIFS(Bank_Statement!$F$6:$F$303,Bank_Statement!$I$6:$I$303,"Not in books",Bank_Statement!$F$6:$F$303,">0") -> 188865 | D22: Book interest. Trace the unidentified deposit and clear it from the suspense account
A23: In bank, not in books: debits | B23: =COUNTIFS(Bank_Statement!$I$6:$I$303,"Not in books",Bank_Statement!$F$6:$F$303,"<0") -> 2 | C23: =SUMIFS(Bank_Statement!$F$6:$F$303,Bank_Statement!$I$6:$I$303,"Not in books",Bank_Statement!$F$6:$F$303,"<0") -> -1002 | D23: Book bank charges
A24: Open items needing action | B24: =SUM(B19:B23) -> 11
A26: Journal entries to pass for items found only in the bank statement
A27: Entry | B27: Debit | C27: Credit | D27: Amount (₹)
A28: Bank charges and cheque return charges | B28: Bank charges | C28: Bank | D28: =-SUMIFS(Bank_Statement!$F$6:$F$303,Bank_Statement!$I$6:$I$303,"Not in books",Bank_Statement!$H$6:$H$303,"Bank charges")-SUMIFS(Bank_Statement!$F$6:$F$303,Bank_Statement!$I$6:$I$303,"Not in books",Bank_Statement!$H$6:$H$303,"Cheque return charges") -> 1002
A29: Interest credited by the bank | B29: Bank | C29: Interest income | D29: =SUMIFS(Bank_Statement!$F$6:$F$303,Bank_Statement!$I$6:$I$303,"Not in books",Bank_Statement!$H$6:$H$303,"Interest") -> 3865
A30: Deposit received, sender not identified | B30: Bank | C30: Unidentified receipts (suspense) | D30: =SUMIFS(Bank_Statement!$F$6:$F$303,Bank_Statement!$I$6:$I$303,"Not in books",Bank_Statement!$H$6:$H$303,"Unidentified credit") -> 185000
A32: Amount differences and timing items are not journalised here: they need a check first or clear on their own.

Sheet Receivables
A1: Receivables ageing
A2: Built from the sales ledger at the as-of date on Setup. Ageing counts days past the due date.
A3: Ageing summary
A4: Bucket | B4: Amount (₹) | C4: % of outstanding | D4: Invoices
A5: Not yet due | B5: =SUMIFS(Sales_Ledger!$I$6:$I$285,Sales_Ledger!$K$6:$K$285,A5) -> 10689934 | C5: =IF($B$10=0,0,B5/$B$10) -> 0.63824198 | D5: =COUNTIFS(Sales_Ledger!$K$6:$K$285,A5) -> 44
A6: 1-30 days | B6: =SUMIFS(Sales_Ledger!$I$6:$I$285,Sales_Ledger!$K$6:$K$285,A6) -> 3674046 | C6: =IF($B$10=0,0,B6/$B$10) -> 0.21935873 | D6: =COUNTIFS(Sales_Ledger!$K$6:$K$285,A6) -> 18
A7: 31-60 days | B7: =SUMIFS(Sales_Ledger!$I$6:$I$285,Sales_Ledger!$K$6:$K$285,A7) -> 826290 | C7: =IF($B$10=0,0,B7/$B$10) -> 0.049333603 | D7: =COUNTIFS(Sales_Ledger!$K$6:$K$285,A7) -> 5
A8: 61-90 days | B8: =SUMIFS(Sales_Ledger!$I$6:$I$285,Sales_Ledger!$K$6:$K$285,A8) -> 4228 | C8: =IF($B$10=0,0,B8/$B$10) -> 0.00025243253 | D8: =COUNTIFS(Sales_Ledger!$K$6:$K$285,A8) -> 2
A9: Over 90 days | B9: =SUMIFS(Sales_Ledger!$I$6:$I$285,Sales_Ledger!$K$6:$K$285,A9) -> 1554532 | C9: =IF($B$10=0,0,B9/$B$10) -> 0.092813255 | D9: =COUNTIFS(Sales_Ledger!$K$6:$K$285,A9) -> 13
A10: Total outstanding | B10: =SUM(B5:B9) -> 16749030 | D10: =SUM(D5:D9) -> 82
A12: Billed in the period (₹) | B12: =SUMIFS(Sales_Ledger!$E$6:$E$285,Sales_Ledger!$B$6:$B$285,">="&Setup!$B$6,Sales_Ledger!$B$6:$B$285,"<="&Setup!$B$5) -> 62032522
A13: Days in the period | B13: =Setup!$B$5-Setup!$B$6+1 -> 183
A14: Days sales outstanding | B14: =IF(B12=0,0,B10/B12*B13) -> 49.410735 | C14: Outstanding / billed in the period x days in the period
A16: By customer
A17: Customer | B17: Region | C17: Billed (₹) | D17: Collected (₹) | E17: Outstanding (₹) | F17: Not yet due | G17: 1-30 days | H17: 31-60 days | I17: 61-90 days | J17: Over 90 days | K17: % overdue
A18: =Setup!A13 -> Hooghly Foods, Kolkata | B18: =Setup!B13 -> East | C18: =SUMIFS(Sales_Ledger!$E$6:$E$285,Sales_Ledger!$C$6:$C$285,$A18) -> 7733653 | D18: =SUMIFS(Sales_Ledger!$H$6:$H$285,Sales_Ledger!$C$6:$C$285,$A18) -> 6500099 | E18: =C18-D18 -> 1233554 | F18: =SUMIFS(Sales_Ledger!$I$6:$I$285,Sales_Ledger!$C$6:$C$285,$A18,Sales_Ledger!$K$6:$K$285,F$17) -> 826580 | G18: =SUMIFS(Sales_Ledger!$I$6:$I$285,Sales_Ledger!$C$6:$C$285,$A18,Sales_Ledger!$K$6:$K$285,G$17) -> 406974 | H18: =SUMIFS(Sales_Ledger!$I$6:$I$285,Sales_Ledger!$C$6:$C$285,$A18,Sales_Ledger!$K$6:$K$285,H$17) -> 0 | I18: =SUMIFS(Sales_Ledger!$I$6:$I$285,Sales_Ledger!$C$6:$C$285,$A18,Sales_Ledger!$K$6:$K$285,I$17) -> 0 | J18: =SUMIFS(Sales_Ledger!$I$6:$I$285,Sales_Ledger!$C$6:$C$285,$A18,Sales_Ledger!$K$6:$K$285,J$17) -> 0 | K18: =IF(E18=0,0,(E18-F18)/E18) -> 0.32991989
A19: =Setup!A14 -> Brahmaputra Traders, Guwahati | B19: =Setup!B14 -> East | C19: =SUMIFS(Sales_Ledger!$E$6:$E$285,Sales_Ledger!$C$6:$C$285,$A19) -> 4643892 | D19: =SUMIFS(Sales_Ledger!$H$6:$H$285,Sales_Ledger!$C$6:$C$285,$A19) -> 4106564 | E19: =C19-D19 -> 537328 | F19: =SUMIFS(Sales_Ledger!$I$6:$I$285,Sales_Ledger!$C$6:$C$285,$A19,Sales_Ledger!$K$6:$K$285,F$17) -> 123903 | G19: =SUMIFS(Sales_Ledger!$I$6:$I$285,Sales_Ledger!$C$6:$C$285,$A19,Sales_Ledger!$K$6:$K$285,G$17) -> 408782 | H19: =SUMIFS(Sales_Ledger!$I$6:$I$285,Sales_Ledger!$C$6:$C$285,$A19,Sales_Ledger!$K$6:$K$285,H$17) -> 0 | I19: =SUMIFS(Sales_Ledger!$I$6:$I$285,Sales_Ledger!$C$6:$C$285,$A19,Sales_Ledger!$K$6:$K$285,I$17) -> 0 | J19: =SUMIFS(Sales_Ledger!$I$6:$I$285,Sales_Ledger!$C$6:$C$285,$A19,Sales_Ledger!$K$6:$K$285,J$17) -> 4643 | K19: =IF(E19=0,0,(E19-F19)/E19) -> 0.769409
A20: =Setup!A15 -> Magadh Agencies, Patna | B20: =Setup!B15 -> East | C20: =SUMIFS(Sales_Ledger!$E$6:$E$285,Sales_Ledger!$C$6:$C$285,$A20) -> 3794895 | D20: =SUMIFS(Sales_Ledger!$H$6:$H$285,Sales_Ledger!$C$6:$C$285,$A20) -> 2929988 | E20: =C20-D20 -> 864907 | F20: =SUMIFS(Sales_Ledger!$I$6:$I$285,Sales_Ledger!$C$6:$C$285,$A20,Sales_Ledger!$K$6:$K$285,F$17) -> 838609 | G20: =SUMIFS(Sales_Ledger!$I$6:$I$285,Sales_Ledger!$C$6:$C$285,$A20,Sales_Ledger!$K$6:$K$285,G$17) -> 20438 | H20: =SUMIFS(Sales_Ledger!$I$6:$I$285,Sales_Ledger!$C$6:$C$285,$A20,Sales_Ledger!$K$6:$K$285,H$17) -> 0 | I20: =SUMIFS(Sales_Ledger!$I$6:$I$285,Sales_Ledger!$C$6:$C$285,$A20,Sales_Ledger!$K$6:$K$285,I$17) -> 0 | J20: =SUMIFS(Sales_Ledger!$I$6:$I$285,Sales_Ledger!$C$6:$C$285,$A20,Sales_Ledger!$K$6:$K$285,J$17) -> 5860 | K20: =IF(E20=0,0,(E20-F20)/E20) -> 0.030405581
A21: =Setup!A16 -> Konkan Distributors, Mumbai | B21: =Setup!B16 -> West | C21: =SUMIFS(Sales_Ledger!$E$6:$E$285,Sales_Ledger!$C$6:$C$285,$A21) -> 6340605 | D21: =SUMIFS(Sales_Ledger!$H$6:$H$285,Sales_Ledger!$C$6:$C$285,$A21) -> 5558217 | E21: =C21-D21 -> 782388 | F21: =SUMIFS(Sales_Ledger!$I$6:$I$285,Sales_Ledger!$C$6:$C$285,$A21,Sales_Ledger!$K$6:$K$285,F$17) -> 592501 | G21: =SUMIFS(Sales_Ledger!$I$6:$I$285,Sales_Ledger!$C$6:$C$285,$A21,Sales_Ledger!$K$6:$K$285,G$17) -> 184435 | H21: =SUMIFS(Sales_Ledger!$I$6:$I$285,Sales_Ledger!$C$6:$C$285,$A21,Sales_Ledger!$K$6:$K$285,H$17) -> 5452 | I21: =SUMIFS(Sales_Ledger!$I$6:$I$285,Sales_Ledger!$C$6:$C$285,$A21,Sales_Ledger!$K$6:$K$285,I$17) -> 0 | J21: =SUMIFS(Sales_Ledger!$I$6:$I$285,Sales_Ledger!$C$6:$C$285,$A21,Sales_Ledger!$K$6:$K$285,J$17) -> 0 | K21: =IF(E21=0,0,(E21-F21)/E21) -> 0.24270183
A22: =Setup!A17 -> Narmada Foods, Surat | B22: =Setup!B17 -> West | C22: =SUMIFS(Sales_Ledger!$E$6:$E$285,Sales_Ledger!$C$6:$C$285,$A22) -> 4224659 | D22: =SUMIFS(Sales_Ledger!$H$6:$H$285,Sales_Ledger!$C$6:$C$285,$A22) -> 3179011 | E22: =C22-D22 -> 1045648 | F22: =SUMIFS(Sales_Ledger!$I$6:$I$285,Sales_Ledger!$C$6:$C$285,$A22,Sales_Ledger!$K$6:$K$285,F$17) -> 1044206 | G22: =SUMIFS(Sales_Ledger!$I$6:$I$285,Sales_Ledger!$C$6:$C$285,$A22,Sales_Ledger!$K$6:$K$285,G$17) -> 0 | H22: =SUMIFS(Sales_Ledger!$I$6:$I$285,Sales_Ledger!$C$6:$C$285,$A22,Sales_Ledger!$K$6:$K$285,H$17) -> 0 | I22: =SUMIFS(Sales_Ledger!$I$6:$I$285,Sales_Ledger!$C$6:$C$285,$A22,Sales_Ledger!$K$6:$K$285,I$17) -> 1442 | J22: =SUMIFS(Sales_Ledger!$I$6:$I$285,Sales_Ledger!$C$6:$C$285,$A22,Sales_Ledger!$K$6:$K$285,J$17) -> 0 | K22: =IF(E22=0,0,(E22-F22)/E22) -> 0.0013790492
A23: =Setup!A18 -> Marwar Agencies, Jaipur | B23: =Setup!B18 -> West | C23: =SUMIFS(Sales_Ledger!$E$6:$E$285,Sales_Ledger!$C$6:$C$285,$A23) -> 2590347 | D23: =SUMIFS(Sales_Ledger!$H$6:$H$285,Sales_Ledger!$C$6:$C$285,$A23) -> 1780891 | E23: =C23-D23 -> 809456 | F23: =SUMIFS(Sales_Ledger!$I$6:$I$285,Sales_Ledger!$C$6:$C$285,$A23,Sales_Ledger!$K$6:$K$285,F$17) -> 482881 | G23: =SUMIFS(Sales_Ledger!$I$6:$I$285,Sales_Ledger!$C$6:$C$285,$A23,Sales_Ledger!$K$6:$K$285,G$17) -> 326575 | H23: =SUMIFS(Sales_Ledger!$I$6:$I$285,Sales_Ledger!$C$6:$C$285,$A23,Sales_Ledger!$K$6:$K$285,H$17) -> 0 | I23: =SUMIFS(Sales_Ledger!$I$6:$I$285,Sales_Ledger!$C$6:$C$285,$A23,Sales_Ledger!$K$6:$K$285,I$17) -> 0 | J23: =SUMIFS(Sales_Ledger!$I$6:$I$285,Sales_Ledger!$C$6:$C$285,$A23,Sales_Ledger!$K$6:$K$285,J$17) -> 0 | K23: =IF(E23=0,0,(E23-F23)/E23) -> 0.40344997
A24: =Setup!A19 -> Yamuna Traders, Delhi | B24: =Setup!B19 -> North | C24: =SUMIFS(Sales_Ledger!$E$6:$E$285,Sales_Ledger!$C$6:$C$285,$A24) -> 7641113 | D24: =SUMIFS(Sales_Ledger!$H$6:$H$285,Sales_Ledger!$C$6:$C$285,$A24) -> 5972885 | E24: =C24-D24 -> 1668228 | F24: =SUMIFS(Sales_Ledger!$I$6:$I$285,Sales_Ledger!$C$6:$C$285,$A24,Sales_Ledger!$K$6:$K$285,F$17) -> 1657597 | G24: =SUMIFS(Sales_Ledger!$I$6:$I$285,Sales_Ledger!$C$6:$C$285,$A24,Sales_Ledger!$K$6:$K$285,G$17) -> 0 | H24: =SUMIFS(Sales_Ledger!$I$6:$I$285,Sales_Ledger!$C$6:$C$285,$A24,Sales_Ledger!$K$6:$K$285,H$17) -> 0 | I24: =SUMIFS(Sales_Ledger!$I$6:$I$285,Sales_Ledger!$C$6:$C$285,$A24,Sales_Ledger!$K$6:$K$285,I$17) -> 2786 | J24: =SUMIFS(Sales_Ledger!$I$6:$I$285,Sales_Ledger!$C$6:$C$285,$A24,Sales_Ledger!$K$6:$K$285,J$17) -> 7845 | K24: =IF(E24=0,0,(E24-F24)/E24) -> 0.0063726301
A25: =Setup!A20 -> Satluj Foods, Ludhiana | B25: =Setup!B20 -> North | C25: =SUMIFS(Sales_Ledger!$E$6:$E$285,Sales_Ledger!$C$6:$C$285,$A25) -> 6759487 | D25: =SUMIFS(Sales_Ledger!$H$6:$H$285,Sales_Ledger!$C$6:$C$285,$A25) -> 5187052 | E25: =C25-D25 -> 1572435 | F25: =SUMIFS(Sales_Ledger!$I$6:$I$285,Sales_Ledger!$C$6:$C$285,$A25,Sales_Ledger!$K$6:$K$285,F$17) -> 1353803 | G25: =SUMIFS(Sales_Ledger!$I$6:$I$285,Sales_Ledger!$C$6:$C$285,$A25,Sales_Ledger!$K$6:$K$285,G$17) -> 207841 | H25: =SUMIFS(Sales_Ledger!$I$6:$I$285,Sales_Ledger!$C$6:$C$285,$A25,Sales_Ledger!$K$6:$K$285,H$17) -> 6223 | I25: =SUMIFS(Sales_Ledger!$I$6:$I$285,Sales_Ledger!$C$6:$C$285,$A25,Sales_Ledger!$K$6:$K$285,I$17) -> 0 | J25: =SUMIFS(Sales_Ledger!$I$6:$I$285,Sales_Ledger!$C$6:$C$285,$A25,Sales_Ledger!$K$6:$K$285,J$17) -> 4568 | K25: =IF(E25=0,0,(E25-F25)/E25) -> 0.13904041
A26: =Setup!A21 -> Doon Distributors, Dehradun | B26: =Setup!B21 -> North | C26: =SUMIFS(Sales_Ledger!$E$6:$E$285,Sales_Ledger!$C$6:$C$285,$A26) -> 3685252 | D26: =SUMIFS(Sales_Ledger!$H$6:$H$285,Sales_Ledger!$C$6:$C$285,$A26) -> 2617658 | E26: =C26-D26 -> 1067594 | F26: =SUMIFS(Sales_Ledger!$I$6:$I$285,Sales_Ledger!$C$6:$C$285,$A26,Sales_Ledger!$K$6:$K$285,F$17) -> 794077 | G26: =SUMIFS(Sales_Ledger!$I$6:$I$285,Sales_Ledger!$C$6:$C$285,$A26,Sales_Ledger!$K$6:$K$285,G$17) -> 268288 | H26: =SUMIFS(Sales_Ledger!$I$6:$I$285,Sales_Ledger!$C$6:$C$285,$A26,Sales_Ledger!$K$6:$K$285,H$17) -> 0 | I26: =SUMIFS(Sales_Ledger!$I$6:$I$285,Sales_Ledger!$C$6:$C$285,$A26,Sales_Ledger!$K$6:$K$285,I$17) -> 0 | J26: =SUMIFS(Sales_Ledger!$I$6:$I$285,Sales_Ledger!$C$6:$C$285,$A26,Sales_Ledger!$K$6:$K$285,J$17) -> 5229 | K26: =IF(E26=0,0,(E26-F26)/E26) -> 0.25619945
A27: =Setup!A22 -> Awadh Agencies, Lucknow | B27: =Setup!B22 -> North | C27: =SUMIFS(Sales_Ledger!$E$6:$E$285,Sales_Ledger!$C$6:$C$285,$A27) -> 4570779 | D27: =SUMIFS(Sales_Ledger!$H$6:$H$285,Sales_Ledger!$C$6:$C$285,$A27) -> 841938 | E27: =C27-D27 -> 3728841 | F27: =SUMIFS(Sales_Ledger!$I$6:$I$285,Sales_Ledger!$C$6:$C$285,$A27,Sales_Ledger!$K$6:$K$285,F$17) -> 775651 | G27: =SUMIFS(Sales_Ledger!$I$6:$I$285,Sales_Ledger!$C$6:$C$285,$A27,Sales_Ledger!$K$6:$K$285,G$17) -> 669941 | H27: =SUMIFS(Sales_Ledger!$I$6:$I$285,Sales_Ledger!$C$6:$C$285,$A27,Sales_Ledger!$K$6:$K$285,H$17) -> 771700 | I27: =SUMIFS(Sales_Ledger!$I$6:$I$285,Sales_Ledger!$C$6:$C$285,$A27,Sales_Ledger!$K$6:$K$285,I$17) -> 0 | J27: =SUMIFS(Sales_Ledger!$I$6:$I$285,Sales_Ledger!$C$6:$C$285,$A27,Sales_Ledger!$K$6:$K$285,J$17) -> 1511549 | K27: =IF(E27=0,0,(E27-F27)/E27) -> 0.79198604
A28: =Setup!A23 -> Cauvery Foods, Bengaluru | B28: =Setup!B23 -> South | C28: =SUMIFS(Sales_Ledger!$E$6:$E$285,Sales_Ledger!$C$6:$C$285,$A28) -> 5181545 | D28: =SUMIFS(Sales_Ledger!$H$6:$H$285,Sales_Ledger!$C$6:$C$285,$A28) -> 4043492 | E28: =C28-D28 -> 1138053 | F28: =SUMIFS(Sales_Ledger!$I$6:$I$285,Sales_Ledger!$C$6:$C$285,$A28,Sales_Ledger!$K$6:$K$285,F$17) -> 487228 | G28: =SUMIFS(Sales_Ledger!$I$6:$I$285,Sales_Ledger!$C$6:$C$285,$A28,Sales_Ledger!$K$6:$K$285,G$17) -> 645143 | H28: =SUMIFS(Sales_Ledger!$I$6:$I$285,Sales_Ledger!$C$6:$C$285,$A28,Sales_Ledger!$K$6:$K$285,H$17) -> 0 | I28: =SUMIFS(Sales_Ledger!$I$6:$I$285,Sales_Ledger!$C$6:$C$285,$A28,Sales_Ledger!$K$6:$K$285,I$17) -> 0 | J28: =SUMIFS(Sales_Ledger!$I$6:$I$285,Sales_Ledger!$C$6:$C$285,$A28,Sales_Ledger!$K$6:$K$285,J$17) -> 5682 | K28: =IF(E28=0,0,(E28-F28)/E28) -> 0.57187583
A29: =Setup!A24 -> Coromandel Traders, Chennai | B29: =Setup!B24 -> South | C29: =SUMIFS(Sales_Ledger!$E$6:$E$285,Sales_Ledger!$C$6:$C$285,$A29) -> 5033109 | D29: =SUMIFS(Sales_Ledger!$H$6:$H$285,Sales_Ledger!$C$6:$C$285,$A29) -> 4552801 | E29: =C29-D29 -> 480308 | F29: =SUMIFS(Sales_Ledger!$I$6:$I$285,Sales_Ledger!$C$6:$C$285,$A29,Sales_Ledger!$K$6:$K$285,F$17) -> 480308 | G29: =SUMIFS(Sales_Ledger!$I$6:$I$285,Sales_Ledger!$C$6:$C$285,$A29,Sales_Ledger!$K$6:$K$285,G$17) -> 0 | H29: =SUMIFS(Sales_Ledger!$I$6:$I$285,Sales_Ledger!$C$6:$C$285,$A29,Sales_Ledger!$K$6:$K$285,H$17) -> 0 | I29: =SUMIFS(Sales_Ledger!$I$6:$I$285,Sales_Ledger!$C$6:$C$285,$A29,Sales_Ledger!$K$6:$K$285,I$17) -> 0 | J29: =SUMIFS(Sales_Ledger!$I$6:$I$285,Sales_Ledger!$C$6:$C$285,$A29,Sales_Ledger!$K$6:$K$285,J$17) -> 0 | K29: =IF(E29=0,0,(E29-F29)/E29) -> 0
... A31: =Setup!A26 -> Periyar Agencies, Kochi | B31: =Setup!B26 -> South | C31: =SUMIFS(Sales_Ledger!$E$6:$E$285,Sales_Ledger!$C$6:$C$285,$A31) -> 2860643 | D31: =SUMIFS(Sales_Ledger!$H$6:$H$285,Sales_Ledger!$C$6:$C$285,$A31) -> 2277163 | E31: =C31-D31 -> 583480 | F31: =SUMIFS(Sales_Ledger!$I$6:$I$285,Sales_Ledger!$C$6:$C$285,$A31,Sales_Ledger!$K$6:$K$285,F$17) -> 344326 | G31: =SUMIFS(Sales_Ledger!$I$6:$I$285,Sales_Ledger!$C$6:$C$285,$A31,Sales_Ledger!$K$6:$K$285,G$17) -> 196239 | H31: =SUMIFS(Sales_Ledger!$I$6:$I$285,Sales_Ledger!$C$6:$C$285,$A31,Sales_Ledger!$K$6:$K$285,H$17) -> 42915 | I31: =SUMIFS(Sales_Ledger!$I$6:$I$285,Sales_Ledger!$C$6:$C$285,$A31,Sales_Ledger!$K$6:$K$285,I$17) -> 0 | J31: =SUMIFS(Sales_Ledger!$I$6:$I$285,Sales_Ledger!$C$6:$C$285,$A31,Sales_Ledger!$K$6:$K$285,J$17) -> 0 | K31: =IF(E31=0,0,(E31-F31)/E31) -> 0.40987523
A32: Total | C32: =SUM(C18:C31) -> 71784003 | D32: =SUM(D18:D31) -> 55034973 | E32: =SUM(E18:E31) -> 16749030 | F32: =SUM(F18:F31) -> 10689934 | G32: =SUM(G18:G31) -> 3674046 | H32: =SUM(H18:H31) -> 826290 | I32: =SUM(I18:I31) -> 4228 | J32: =SUM(J18:J31) -> 1554532 | K32: =IF(E32=0,0,(E32-F32)/E32) -> 0.36175802
A34: By region
A35: Region | B35: Billed (₹) | C35: Collected (₹) | D35: Outstanding (₹) | E35: Overdue (₹) | F35: % overdue
A36: East | B36: =SUMIFS($C$18:$C$31,$B$18:$B$31,$A36) -> 16172440 | C36: =SUMIFS($D$18:$D$31,$B$18:$B$31,$A36) -> 13536651 | D36: =SUMIFS($E$18:$E$31,$B$18:$B$31,$A36) -> 2635789 | E36: =D36-SUMIFS($F$18:$F$31,$B$18:$B$31,$A36) -> 846697 | F36: =IF(D36=0,0,E36/D36) -> 0.32123095
A37: West | B37: =SUMIFS($C$18:$C$31,$B$18:$B$31,$A37) -> 13155611 | C37: =SUMIFS($D$18:$D$31,$B$18:$B$31,$A37) -> 10518119 | D37: =SUMIFS($E$18:$E$31,$B$18:$B$31,$A37) -> 2637492 | E37: =D37-SUMIFS($F$18:$F$31,$B$18:$B$31,$A37) -> 517904 | F37: =IF(D37=0,0,E37/D37) -> 0.1963623
A38: North | B38: =SUMIFS($C$18:$C$31,$B$18:$B$31,$A38) -> 22656631 | C38: =SUMIFS($D$18:$D$31,$B$18:$B$31,$A38) -> 14619533 | D38: =SUMIFS($E$18:$E$31,$B$18:$B$31,$A38) -> 8037098 | E38: =D38-SUMIFS($F$18:$F$31,$B$18:$B$31,$A38) -> 3455970 | F38: =IF(D38=0,0,E38/D38) -> 0.43000222
A39: South | B39: =SUMIFS($C$18:$C$31,$B$18:$B$31,$A39) -> 19799321 | C39: =SUMIFS($D$18:$D$31,$B$18:$B$31,$A39) -> 16360670 | D39: =SUMIFS($E$18:$E$31,$B$18:$B$31,$A39) -> 3438651 | E39: =D39-SUMIFS($F$18:$F$31,$B$18:$B$31,$A39) -> 1238525 | F39: =IF(D39=0,0,E39/D39) -> 0.36017758
A40: Total | B40: =SUM(B36:B39) -> 71784003 | C40: =SUM(C36:C39) -> 55034973 | D40: =SUM(D36:D39) -> 16749030 | E40: =SUM(E36:E39) -> 6059096 | F40: =IF(D40=0,0,E40/D40) -> 0.36175802

Sheet Controls
A1: Control checks
A2: Each check compares two figures that must agree. PASS means they do.
D3: =COUNTIF(F6:F25,"PASS")&" of "&COUNTA(F6:F25)&" checks passed" -> 18 of 18 checks passed
A5: # | B5: Area | C5: Check | D5: Expected | E5: Actual | F5: Result | G5: Comment
A6: 1 | B6: Sales | C6: Invoice numbers that appear more than once | D6: 0 | E6: =SUMPRODUCT((COUNTIF(Sales_Ledger!$A$6:$A$285,Sales_Ledger!$A$6:$A$285)>1)*1) -> 0 | F6: =IF(ABS(E6-D6)<=0.5,"PASS","REVIEW") -> PASS
A7: 2 | B7: Sales | C7: Invoices with a customer missing from Setup | D7: 0 | E7: =SUMPRODUCT((COUNTIF(Setup!$A$13:$A$26,Sales_Ledger!$C$6:$C$285)=0)*1) -> 0 | F7: =IF(ABS(E7-D7)<=0.5,"PASS","REVIEW") -> PASS
A8: 3 | B8: Collections | C8: Receipts that point to a non-existent invoice | D8: 0 | E8: =SUMPRODUCT((COUNTIF(Sales_Ledger!$A$6:$A$285,Collections!$C$6:$C$239)=0)*1) -> 0 | F8: =IF(ABS(E8-D8)<=0.5,"PASS","REVIEW") -> PASS
